[2025-08-24T05:19:03.213+0000] {local_task_job_runner.py:120} INFO - ::group::Pre task execution logs
[2025-08-24T05:19:03.301+0000] {taskinstance.py:2076} INFO - Dependencies all met for dep_context=non-requeueable deps ti=<TaskInstance: stock_pipeline_dag.fetch_and_upsert scheduled__2025-08-24T04:00:00+00:00 [queued]>
[2025-08-24T05:19:03.322+0000] {taskinstance.py:2076} INFO - Dependencies all met for dep_context=requeueable deps ti=<TaskInstance: stock_pipeline_dag.fetch_and_upsert scheduled__2025-08-24T04:00:00+00:00 [queued]>
[2025-08-24T05:19:03.324+0000] {taskinstance.py:2306} INFO - Starting attempt 1 of 2
[2025-08-24T05:19:03.358+0000] {taskinstance.py:2330} INFO - Executing <Task(PythonOperator): fetch_and_upsert> on 2025-08-24 04:00:00+00:00
[2025-08-24T05:19:03.374+0000] {standard_task_runner.py:63} INFO - Started process 238 to run task
[2025-08-24T05:19:03.384+0000] {standard_task_runner.py:90} INFO - Running: ['***', 'tasks', 'run', 'stock_pipeline_dag', 'fetch_and_upsert', 'scheduled__2025-08-24T04:00:00+00:00', '--job-id', '3', '--raw', '--subdir', 'DAGS_FOLDER/stock_pipeline_dag.py', '--cfg-path', '/tmp/tmp9ntdpod6']
[2025-08-24T05:19:03.393+0000] {standard_task_runner.py:91} INFO - Job 3: Subtask fetch_and_upsert
[2025-08-24T05:19:03.577+0000] {task_command.py:426} INFO - Running <TaskInstance: stock_pipeline_dag.fetch_and_upsert scheduled__2025-08-24T04:00:00+00:00 [running]> on host e5f40dd73754
[2025-08-24T05:19:03.849+0000] {taskinstance.py:2648} INFO - Exporting env vars: AIRFLOW_CTX_DAG_OWNER='data-eng' AIRFLOW_CTX_DAG_ID='stock_pipeline_dag' AIRFLOW_CTX_TASK_ID='fetch_and_upsert' AIRFLOW_CTX_EXECUTION_DATE='2025-08-24T04:00:00+00:00' AIRFLOW_CTX_TRY_NUMBER='1' AIRFLOW_CTX_DAG_RUN_ID='scheduled__2025-08-24T04:00:00+00:00'
[2025-08-24T05:19:03.851+0000] {taskinstance.py:430} INFO - ::endgroup::
[2025-08-24T05:19:05.148+0000] {taskinstance.py:441} INFO - ::group::Post task execution logs
[2025-08-24T05:19:05.151+0000] {taskinstance.py:2905} ERROR - Task failed with exception
Traceback (most recent call last):
  File "/home/airflow/.local/lib/python3.11/site-packages/airflow/models/taskinstance.py", line 465, in _execute_task
    result = _execute_callable(context=context, **execute_callable_kwargs)
             ^^^^^^^^^^^^^^^^^^^^^^^^^^^^^^^^^^^^^^^^^^^^^^^^^^^^^^^^^^^^^
  File "/home/airflow/.local/lib/python3.11/site-packages/airflow/models/taskinstance.py", line 432, in _execute_callable
    return execute_callable(context=context, **execute_callable_kwargs)
           ^^^^^^^^^^^^^^^^^^^^^^^^^^^^^^^^^^^^^^^^^^^^^^^^^^^^^^^^^^^^
  File "/home/airflow/.local/lib/python3.11/site-packages/airflow/models/baseoperator.py", line 400, in wrapper
    return func(self, *args, **kwargs)
           ^^^^^^^^^^^^^^^^^^^^^^^^^^^
  File "/home/airflow/.local/lib/python3.11/site-packages/airflow/operators/python.py", line 235, in execute
    return_value = self.execute_callable()
                   ^^^^^^^^^^^^^^^^^^^^^^^
  File "/home/airflow/.local/lib/python3.11/site-packages/airflow/operators/python.py", line 252, in execute_callable
    return self.python_callable(*self.op_args, **self.op_kwargs)
           ^^^^^^^^^^^^^^^^^^^^^^^^^^^^^^^^^^^^^^^^^^^^^^^^^^^^^
  File "/opt/airflow/dags/stock_pipeline_dag.py", line 47, in fetch_and_upsert
    raise RuntimeError(f"Fetch & upsert failed: {res.stderr}")
RuntimeError: Fetch & upsert failed: Traceback (most recent call last):
  File "/opt/***/scripts/fetch_and_upsert.py", line 106, in <module>
    main()
  File "/opt/***/scripts/fetch_and_upsert.py", line 95, in main
    create_table()
  File "/opt/***/scripts/fetch_and_upsert.py", line 58, in create_table
    with get_conn() as conn, conn.cursor() as cur:
         ^^^^^^^^^^
  File "/opt/***/scripts/fetch_and_upsert.py", line 53, in get_conn
    return psycopg2.connect(
           ^^^^^^^^^^^^^^^^^
  File "/home/***/.local/lib/python3.11/site-packages/psycopg2/__init__.py", line 122, in connect
    conn = _connect(dsn, connection_factory=connection_factory, **kwasync)
           ^^^^^^^^^^^^^^^^^^^^^^^^^^^^^^^^^^^^^^^^^^^^^^^^^^^^^^^^^^^^^^^
psycopg2.OperationalError: connection to server at "postgres" (172.19.0.2), port 5433 failed: Connection refused
	Is the server running on that host and accepting TCP/IP connections?


[2025-08-24T05:19:05.203+0000] {taskinstance.py:1206} INFO - Marking task as UP_FOR_RETRY. dag_id=stock_pipeline_dag, task_id=fetch_and_upsert, run_id=scheduled__2025-08-24T04:00:00+00:00, execution_date=20250824T040000, start_date=20250824T051903, end_date=20250824T051905
[2025-08-24T05:19:05.238+0000] {standard_task_runner.py:110} ERROR - Failed to execute job 3 for task fetch_and_upsert (Fetch & upsert failed: Traceback (most recent call last):
  File "/opt/***/scripts/fetch_and_upsert.py", line 106, in <module>
    main()
  File "/opt/***/scripts/fetch_and_upsert.py", line 95, in main
    create_table()
  File "/opt/***/scripts/fetch_and_upsert.py", line 58, in create_table
    with get_conn() as conn, conn.cursor() as cur:
         ^^^^^^^^^^
  File "/opt/***/scripts/fetch_and_upsert.py", line 53, in get_conn
    return psycopg2.connect(
           ^^^^^^^^^^^^^^^^^
  File "/home/***/.local/lib/python3.11/site-packages/psycopg2/__init__.py", line 122, in connect
    conn = _connect(dsn, connection_factory=connection_factory, **kwasync)
           ^^^^^^^^^^^^^^^^^^^^^^^^^^^^^^^^^^^^^^^^^^^^^^^^^^^^^^^^^^^^^^^
psycopg2.OperationalError: connection to server at "postgres" (172.19.0.2), port 5433 failed: Connection refused
	Is the server running on that host and accepting TCP/IP connections?

; 238)
[2025-08-24T05:19:05.289+0000] {local_task_job_runner.py:240} INFO - Task exited with return code 1
[2025-08-24T05:19:05.335+0000] {taskinstance.py:3498} INFO - 0 downstream tasks scheduled from follow-on schedule check
[2025-08-24T05:19:05.342+0000] {local_task_job_runner.py:222} INFO - ::endgroup::
